<?xml version="1.0" encoding="utf-8"?>
<!-- This URDF was automatically created by SolidWorks to URDF Exporter! Originally created by Stephen Brawner (brawner@gmail.com) 
     Commit Version: 1.5.1-0-g916b5db  Build Version: 1.5.7152.31018
     For more information, please see http://wiki.ros.org/sw_urdf_exporter -->
<robot
  name="a">
  <link
    name="base_link">
    <inertial>
      <origin
        xyz="0.026821624688902 -4.00085068042316E-05 0.0416160022003314"
        rpy="0 0 0" />
      <mass
        value="0.0528949799675124" />
      <inertia
        ixx="2.70567852420767E-05"
        ixy="-9.67279674333672E-21"
        ixz="7.03793966679837E-06"
        iyy="4.91337224403947E-05"
        iyz="3.14088025332722E-21"
        izz="5.74103078193648E-05" />
    </inertial>
    <visual>
      <origin
        xyz="0 0 0"
        rpy="0 0 0" />
      <geometry>
        <mesh
          filename="package://a/meshes/base_link.STL" />
      </geometry>
      <material
        name="">
        <color
          rgba="1 1 1 1" />
      </material>
    </visual>
    <collision>
      <origin
        xyz="0 0 0"
        rpy="0 0 0" />
      <geometry>
        <mesh
          filename="package://a/meshes/base_link.STL" />
      </geometry>
    </collision>
  </link>
  <link
    name="l_wheel">
    <inertial>
      <origin
        xyz="-6.93889390390723E-18 0 -0.0137281820853482"
        rpy="0 0 0" />
      <mass
        value="0.0139508210573943" />
      <inertia
        ixx="2.89561382218671E-06"
        ixy="-3.70576914423756E-22"
        ixz="1.22157832118606E-23"
        iyy="2.8956138221867E-06"
        iyz="-1.68722755729679E-22"
        izz="5.50325061710386E-06" />
    </inertial>
    <visual>
      <origin
        xyz="0 0 0"
        rpy="0 0 0" />
      <geometry>
        <mesh
          filename="package://a/meshes/l_wheel.STL" />
      </geometry>
      <material
        name="">
        <color
          rgba="1 1 1 1" />
      </material>
    </visual>
    <collision>
      <origin
        xyz="0 0 0"
        rpy="0 0 0" />
      <geometry>
        <mesh
          filename="package://a/meshes/l_wheel.STL" />
      </geometry>
    </collision>
  </link>
  <joint
    name="l_wh"
    type="continuous">
    <origin
      xyz="0 -0.01904 0.026"
      rpy="-1.5708 -1.3685 0" />
    <parent
      link="base_link" />
    <child
      link="l_wheel" />
    <axis
      xyz="0 0 1" />
  </joint>
  <link
    name="r_wheel">
    <inertial>
      <origin
        xyz="-3.81639164714898E-17 2.77555756156289E-17 -0.0137281820853482"
        rpy="0 0 0" />
      <mass
        value="0.0139508210573943" />
      <inertia
        ixx="2.8956138221867E-06"
        ixy="5.29395592033938E-22"
        ixz="-2.52469524042589E-22"
        iyy="2.8956138221867E-06"
        iyz="-2.67527204160234E-22"
        izz="5.50325061710386E-06" />
    </inertial>
    <visual>
      <origin
        xyz="0 0 0"
        rpy="0 0 0" />
      <geometry>
        <mesh
          filename="package://a/meshes/r_wheel.STL" />
      </geometry>
      <material
        name="">
        <color
          rgba="1 1 1 1" />
      </material>
    </visual>
    <collision>
      <origin
        xyz="0 0 0"
        rpy="0 0 0" />
      <geometry>
        <mesh
          filename="package://a/meshes/r_wheel.STL" />
      </geometry>
    </collision>
  </link>
  <joint
    name="r_wh"
    type="continuous">
    <origin
      xyz="0 0.01896 0.026"
      rpy="1.5708 -0.61766 0" />
    <parent
      link="base_link" />
    <child
      link="r_wheel" />
    <axis
      xyz="0 0 -1" />
  </joint>
  <link
    name="caster">
    <inertial>
      <origin
        xyz="3.62452395874513E-09 -0.0148173358863486 3.3551936090559E-09"
        rpy="0 0 0" />
      <mass
        value="0.000511507784206821" />
      <inertia
        ixx="2.52912052371912E-08"
        ixy="-1.49972092281477E-14"
        ixz="-1.4717066777345E-14"
        iyy="2.3449904681603E-09"
        iyz="-1.63975408848506E-14"
        izz="2.4420663846452E-08" />
    </inertial>
    <visual>
      <origin
        xyz="0 0 0"
        rpy="0 0 0" />
      <geometry>
        <mesh
          filename="package://a/meshes/caster.STL" />
      </geometry>
      <material
        name="">
        <color
          rgba="1 1 1 1" />
      </material>
    </visual>
    <collision>
      <origin
        xyz="0 0 0"
        rpy="0 0 0" />
      <geometry>
        <mesh
          filename="package://a/meshes/caster.STL" />
      </geometry>
    </collision>
  </link>
  <joint
    name="ca_a"
    type="continuous">
    <origin
      xyz="0.059996 -4.0009E-05 0.005"
      rpy="-1.5708 0 3.1173" />
    <parent
      link="base_link" />
    <child
      link="caster" />
    <axis
      xyz="0 1 0" />
  </joint>
  <link
    name="ca_in">
    <inertial>
      <origin
        xyz="1.73472347597681E-18 -3.46944695195361E-18 -0.0031609353514942"
        rpy="0 0 0" />
      <mass
        value="0.00115294881037348" />
      <inertia
        ixx="2.21276235145309E-08"
        ixy="-2.17983094040463E-24"
        ixz="-4.65289094561078E-25"
        iyy="2.26814235145309E-08"
        iyz="-3.07607790293157E-24"
        izz="2.12171525368821E-08" />
    </inertial>
    <visual>
      <origin
        xyz="0 0 0"
        rpy="0 0 0" />
      <geometry>
        <mesh
          filename="package://a/meshes/ca_in.STL" />
      </geometry>
      <material
        name="">
        <color
          rgba="1 1 1 1" />
      </material>
    </visual>
    <collision>
      <origin
        xyz="0 0 0"
        rpy="0 0 0" />
      <geometry>
        <mesh
          filename="package://a/meshes/ca_in.STL" />
      </geometry>
    </collision>
  </link>
  <joint
    name="ca_wh"
    type="continuous">
    <origin
      xyz="0 -0.003 0"
      rpy="-3.1416 0 1.0249" />
    <parent
      link="caster" />
    <child
      link="ca_in" />
    <axis
      xyz="0 0 -1" />
  </joint>
    <gazebo>
    <plugin filename="libgazebo_ros_diff_drive.so" name="differential_drive_controller">
      <alwaysOn>true</alwaysOn>
      <updateRate>20</updateRate>
      <leftJoint>r_wh</leftJoint>
      <rightJoint>l_wh</rightJoint>
      <wheelSeparation>0.4</wheelSeparation>
      <wheelDiameter>0.2</wheelDiameter>
      <torque>0.1</torque>
      <commandTopic>cmd_vel</commandTopic>
      <odometryTopic>odom</odometryTopic>
      <odometryFrame>oodm</odometryFrame>
      <robotBaseFrame>base_link</robotBaseFrame>
    </plugin>
  </gazebo>
</robot>